第一种情况：如果您想让 catch 块能够处理 try 块抛出的任何类型的异常，则必须在异常声明的括号内使用省略号 ...，如下所示：
try{
   // 保护代码
}catch(...){
  // 能处理任何异常的代码
}

第二种情况：
#include <iostream>
using namespace std;
 
double division(int a, int b){
   if( b == 0 ){
      throw "Division by zero condition!";
   }
   return (a/b);
}
 
int main (){
   int x = 50;
   int y = 0;
   double z = 0;
   try {
     z = division(x, y);
     cout << z << endl;
   }catch (const char* msg) {
     cerr << msg << endl;
   }
   return 0;
}
由于我们抛出了一个类型为 const char* 的异常，因此，当捕获该异常时，我们必须在 catch 块中使用 const char*。
当上面的代码被编译和执行时，它会产生下列结果：
Division by zero condition!
